[2025-07-13T03:38:05.181+0000] {taskinstance.py:1956} INFO - Dependencies all met for dep_context=non-requeueable deps ti=<TaskInstance: main_etl_pipeline.transform_covid_data manual__2025-07-13T03:37:50.399182+00:00 [queued]>
[2025-07-13T03:38:05.212+0000] {taskinstance.py:1956} INFO - Dependencies all met for dep_context=requeueable deps ti=<TaskInstance: main_etl_pipeline.transform_covid_data manual__2025-07-13T03:37:50.399182+00:00 [queued]>
[2025-07-13T03:38:05.213+0000] {taskinstance.py:2170} INFO - Starting attempt 1 of 1
[2025-07-13T03:38:05.243+0000] {taskinstance.py:2191} INFO - Executing <Task(PythonOperator): transform_covid_data> on 2025-07-13 03:37:50.399182+00:00
[2025-07-13T03:38:05.264+0000] {standard_task_runner.py:60} INFO - Started process 324 to run task
[2025-07-13T03:38:05.272+0000] {standard_task_runner.py:87} INFO - Running: ['***', 'tasks', 'run', 'main_etl_pipeline', 'transform_covid_data', 'manual__2025-07-13T03:37:50.399182+00:00', '--job-id', '8', '--raw', '--subdir', 'DAGS_FOLDER/main_pipeline.py', '--cfg-path', '/tmp/tmptxg5vy8f']
[2025-07-13T03:38:05.277+0000] {standard_task_runner.py:88} INFO - Job 8: Subtask transform_covid_data
[2025-07-13T03:38:05.406+0000] {task_command.py:423} INFO - Running <TaskInstance: main_etl_pipeline.transform_covid_data manual__2025-07-13T03:37:50.399182+00:00 [running]> on host 23913323947a
[2025-07-13T03:38:05.578+0000] {taskinstance.py:2480} INFO - Exporting env vars: AIRFLOW_CTX_DAG_OWNER='***' AIRFLOW_CTX_DAG_ID='main_etl_pipeline' AIRFLOW_CTX_TASK_ID='transform_covid_data' AIRFLOW_CTX_EXECUTION_DATE='2025-07-13T03:37:50.399182+00:00' AIRFLOW_CTX_TRY_NUMBER='1' AIRFLOW_CTX_DAG_RUN_ID='manual__2025-07-13T03:37:50.399182+00:00'
[2025-07-13T03:38:05.603+0000] {taskinstance.py:2698} ERROR - Task failed with exception
Traceback (most recent call last):
  File "/home/airflow/.local/lib/python3.10/site-packages/airflow/models/taskinstance.py", line 433, in _execute_task
    result = execute_callable(context=context, **execute_callable_kwargs)
  File "/home/airflow/.local/lib/python3.10/site-packages/airflow/operators/python.py", line 199, in execute
    return_value = self.execute_callable()
  File "/home/airflow/.local/lib/python3.10/site-packages/airflow/operators/python.py", line 216, in execute_callable
    return self.python_callable(*self.op_args, **self.op_kwargs)
  File "/opt/airflow/dags/transform_covid.py", line 19, in transform_covid_data
    raise ValueError("No se encontraron datos crudos de COVID-19 para transformar.")
ValueError: No se encontraron datos crudos de COVID-19 para transformar.
[2025-07-13T03:38:05.642+0000] {taskinstance.py:1138} INFO - Marking task as FAILED. dag_id=main_etl_pipeline, task_id=transform_covid_data, execution_date=20250713T033750, start_date=20250713T033805, end_date=20250713T033805
[2025-07-13T03:38:05.677+0000] {standard_task_runner.py:107} ERROR - Failed to execute job 8 for task transform_covid_data (No se encontraron datos crudos de COVID-19 para transformar.; 324)
[2025-07-13T03:38:05.727+0000] {local_task_job_runner.py:234} INFO - Task exited with return code 1
[2025-07-13T03:38:05.770+0000] {taskinstance.py:3280} INFO - 0 downstream tasks scheduled from follow-on schedule check
