[2025-07-13T03:59:13.989+0000] {taskinstance.py:1956} INFO - Dependencies all met for dep_context=non-requeueable deps ti=<TaskInstance: main_etl_pipeline.transform_covid_data manual__2025-07-13T03:59:05.098075+00:00 [queued]>
[2025-07-13T03:59:14.005+0000] {taskinstance.py:1956} INFO - Dependencies all met for dep_context=requeueable deps ti=<TaskInstance: main_etl_pipeline.transform_covid_data manual__2025-07-13T03:59:05.098075+00:00 [queued]>
[2025-07-13T03:59:14.006+0000] {taskinstance.py:2170} INFO - Starting attempt 1 of 1
[2025-07-13T03:59:14.026+0000] {taskinstance.py:2191} INFO - Executing <Task(PythonOperator): transform_covid_data> on 2025-07-13 03:59:05.098075+00:00
[2025-07-13T03:59:14.036+0000] {standard_task_runner.py:60} INFO - Started process 308 to run task
[2025-07-13T03:59:14.039+0000] {standard_task_runner.py:87} INFO - Running: ['***', 'tasks', 'run', 'main_etl_pipeline', 'transform_covid_data', 'manual__2025-07-13T03:59:05.098075+00:00', '--job-id', '17', '--raw', '--subdir', 'DAGS_FOLDER/main_pipeline.py', '--cfg-path', '/tmp/tmp1l3uz0jh']
[2025-07-13T03:59:14.042+0000] {standard_task_runner.py:88} INFO - Job 17: Subtask transform_covid_data
[2025-07-13T03:59:14.177+0000] {task_command.py:423} INFO - Running <TaskInstance: main_etl_pipeline.transform_covid_data manual__2025-07-13T03:59:05.098075+00:00 [running]> on host 23913323947a
[2025-07-13T03:59:14.847+0000] {taskinstance.py:2480} INFO - Exporting env vars: AIRFLOW_CTX_DAG_OWNER='***' AIRFLOW_CTX_DAG_ID='main_etl_pipeline' AIRFLOW_CTX_TASK_ID='transform_covid_data' AIRFLOW_CTX_EXECUTION_DATE='2025-07-13T03:59:05.098075+00:00' AIRFLOW_CTX_TRY_NUMBER='1' AIRFLOW_CTX_DAG_RUN_ID='manual__2025-07-13T03:59:05.098075+00:00'
[2025-07-13T03:59:15.072+0000] {logging_mixin.py:188} INFO - DEBUG: Contenido de raw_data recibido en transform_covid_data: None
[2025-07-13T03:59:15.119+0000] {logging_mixin.py:188} INFO - DEBUG: Tipo de raw_data: <class 'NoneType'>
[2025-07-13T03:59:15.135+0000] {logging_mixin.py:188} INFO - ERROR: Datos crudos de COVID-19 inv치lidos o faltantes para transformar.
[2025-07-13T03:59:15.151+0000] {taskinstance.py:2698} ERROR - Task failed with exception
Traceback (most recent call last):
  File "/home/airflow/.local/lib/python3.10/site-packages/airflow/models/taskinstance.py", line 433, in _execute_task
    result = execute_callable(context=context, **execute_callable_kwargs)
  File "/home/airflow/.local/lib/python3.10/site-packages/airflow/operators/python.py", line 199, in execute
    return_value = self.execute_callable()
  File "/home/airflow/.local/lib/python3.10/site-packages/airflow/operators/python.py", line 216, in execute_callable
    return self.python_callable(*self.op_args, **self.op_kwargs)
  File "/opt/airflow/dags/transform_covid.py", line 17, in transform_covid_data
    raise ValueError("No se encontraron datos crudos de COVID-19 v치lidos para transformar.")
ValueError: No se encontraron datos crudos de COVID-19 v치lidos para transformar.
[2025-07-13T03:59:15.310+0000] {taskinstance.py:1138} INFO - Marking task as FAILED. dag_id=main_etl_pipeline, task_id=transform_covid_data, execution_date=20250713T035905, start_date=20250713T035913, end_date=20250713T035915
[2025-07-13T03:59:15.498+0000] {standard_task_runner.py:107} ERROR - Failed to execute job 17 for task transform_covid_data (No se encontraron datos crudos de COVID-19 v치lidos para transformar.; 308)
[2025-07-13T03:59:15.597+0000] {local_task_job_runner.py:234} INFO - Task exited with return code 1
[2025-07-13T03:59:15.731+0000] {taskinstance.py:3280} INFO - 0 downstream tasks scheduled from follow-on schedule check
